<mujoco model="hopper">
  <compiler autolimits="true"/>
  <option integrator="Euler" timestep="0.005"/>
  <worldbody>
    <light pos="0 0 3"/>
    <geom type="plane" size="5 5 0.1" contype="1" conaffinity="1"/>
    <body name="torso" pos="0 0 1.25">
      <joint name="rootx" type="slide" axis="1 0 0"/>
      <joint name="rootz" type="slide" axis="0 0 1"/>
      <joint name="rooty" type="hinge" axis="0 1 0"/>
      <geom type="capsule" fromto="0 0 0 0 0 -0.4" size="0.05" mass="3"
             friction="1 0.005 0.0001" condim="3"/>
      <body name="thigh" pos="0 0 -0.4">
        <joint name="thigh_joint" type="hinge" axis="0 1 0" damping="5"/>
        <geom type="capsule" fromto="0 0 0 0 0 -0.45" size="0.05" mass="3"
               friction="1 0.005 0.0001" condim="3"/>
        <body name="leg" pos="0 0 -0.45">
          <joint name="leg_joint" type="hinge" axis="0 1 0" damping="5"/>
          <geom type="capsule" fromto="0 0 0 0 0 -0.5" size="0.04" mass="3"
                 friction="1 0.005 0.0001" condim="3"/>
          <body name="foot" pos="0 0 -0.5">
            <joint name="foot_joint" type="hinge" axis="0 1 0" damping="5"/>
            <geom type="capsule" fromto="-0.13 0 0 0.16 0 0" size="0.06" mass="2"
                   friction="2 0.005 0.0001" condim="3"/>
          </body>
        </body>
      </body>
    </body>
  </worldbody>
  <actuator>
    <motor joint="thigh_joint" gear="200"/>
    <motor joint="leg_joint" gear="200"/>
    <motor joint="foot_joint" gear="200"/>
  </actuator>
</mujoco>
